test_build_recursive_sequence_generator (__main__.TestExercice) ... FAIL
test_fibonacci_number (__main__.TestExercice) ... ok
test_get_fibonacci_number (__main__.TestExercice) ... ok
test_get_fibonacci_sequence (__main__.TestExercice) ... ok
test_get_sorted_dict_by_decimals (__main__.TestExercice) ... ok

======================================================================
FAIL: test_build_recursive_sequence_generator (__main__.TestExercice)
----------------------------------------------------------------------
Traceback (most recent call last):
  File "C:/Users/romai/OneDrive/Bureau/School/University/poly/INF1007 projet/2021a_c04_ch7_exercices-R0ma01/test_exercice.py", line 81, in test_build_recursive_sequence_generator
    fibo = build_recursive_sequence_generator([0, 1], fibo_def, False)
TypeError: build_recursive_sequence_generator() takes 1 positional argument but 3 were given

During handling of the above exception, another exception occurred:

Traceback (most recent call last):
  File "C:/Users/romai/OneDrive/Bureau/School/University/poly/INF1007 projet/2021a_c04_ch7_exercices-R0ma01/test_exercice.py", line 83, in test_build_recursive_sequence_generator
    self.fail("l'appel échoue")
AssertionError: l'appel échoue

----------------------------------------------------------------------
Ran 5 tests in 0.005s

FAILED (failures=1)
